{
  "examples": [
    {
      "name": "simple_platform",
      "description": "A 3x3 stone platform",
      "blocks": [
        {"x": 0, "y": 0, "z": 0, "block_type": "stone"},
        {"x": 1, "y": 0, "z": 0, "block_type": "stone"},
        {"x": 2, "y": 0, "z": 0, "block_type": "stone"},
        {"x": 0, "y": 0, "z": 1, "block_type": "stone"},
        {"x": 1, "y": 0, "z": 1, "block_type": "stone"},
        {"x": 2, "y": 0, "z": 1, "block_type": "stone"},
        {"x": 0, "y": 0, "z": 2, "block_type": "stone"},
        {"x": 1, "y": 0, "z": 2, "block_type": "stone"},
        {"x": 2, "y": 0, "z": 2, "block_type": "stone"}
      ]
    },
    {
      "name": "tiny_house",
      "description": "A minimal wooden house frame",
      "blocks": [
        {"x": 0, "y": 0, "z": 0, "block_type": "oak_planks"},
        {"x": 1, "y": 0, "z": 0, "block_type": "oak_planks"},
        {"x": 2, "y": 0, "z": 0, "block_type": "oak_planks"},
        {"x": 0, "y": 0, "z": 2, "block_type": "oak_planks"},
        {"x": 1, "y": 0, "z": 2, "block_type": "oak_planks"},
        {"x": 2, "y": 0, "z": 2, "block_type": "oak_planks"},
        {"x": 0, "y": 1, "z": 0, "block_type": "oak_planks"},
        {"x": 2, "y": 1, "z": 0, "block_type": "oak_planks"},
        {"x": 0, "y": 1, "z": 2, "block_type": "oak_planks"},
        {"x": 2, "y": 1, "z": 2, "block_type": "oak_planks"},
        {"x": 0, "y": 2, "z": 0, "block_type": "oak_planks"},
        {"x": 1, "y": 2, "z": 0, "block_type": "oak_planks"},
        {"x": 2, "y": 2, "z": 0, "block_type": "oak_planks"},
        {"x": 0, "y": 2, "z": 2, "block_type": "oak_planks"},
        {"x": 1, "y": 2, "z": 2, "block_type": "oak_planks"},
        {"x": 2, "y": 2, "z": 2, "block_type": "oak_planks"}
      ]
    },
    {
      "name": "tower",
      "description": "A simple 2x2 stone tower, 5 blocks tall",
      "blocks": [
        {"x": 0, "y": 0, "z": 0, "block_type": "cobblestone"},
        {"x": 1, "y": 0, "z": 0, "block_type": "cobblestone"},
        {"x": 0, "y": 0, "z": 1, "block_type": "cobblestone"},
        {"x": 1, "y": 0, "z": 1, "block_type": "cobblestone"},
        {"x": 0, "y": 1, "z": 0, "block_type": "cobblestone"},
        {"x": 1, "y": 1, "z": 0, "block_type": "cobblestone"},
        {"x": 0, "y": 1, "z": 1, "block_type": "cobblestone"},
        {"x": 1, "y": 1, "z": 1, "block_type": "cobblestone"},
        {"x": 0, "y": 2, "z": 0, "block_type": "cobblestone"},
        {"x": 1, "y": 2, "z": 0, "block_type": "cobblestone"},
        {"x": 0, "y": 2, "z": 1, "block_type": "cobblestone"},
        {"x": 1, "y": 2, "z": 1, "block_type": "cobblestone"},
        {"x": 0, "y": 3, "z": 0, "block_type": "cobblestone"},
        {"x": 1, "y": 3, "z": 0, "block_type": "cobblestone"},
        {"x": 0, "y": 3, "z": 1, "block_type": "cobblestone"},
        {"x": 1, "y": 3, "z": 1, "block_type": "cobblestone"},
        {"x": 0, "y": 4, "z": 0, "block_type": "cobblestone"},
        {"x": 1, "y": 4, "z": 0, "block_type": "cobblestone"},
        {"x": 0, "y": 4, "z": 1, "block_type": "cobblestone"},
        {"x": 1, "y": 4, "z": 1, "block_type": "cobblestone"}
      ]
    },
    {
      "name": "small_tower_as_operation",
      "description": "The same 2x2x5 tower as one operation instead of 20 blocks",
      "operations": [
        {"op": "cuboid", "start": [0, 0, 0], "end": [1, 4, 1], "block": "cobblestone"}
      ]
    },
    {
      "name": "stone_hut",
      "description": "Hollow stone hut, open roof, with a carved doorway",
      "operations": [
        {"op": "hollow_box", "start": [0, 0, 0], "end": [6, 4, 6], "block": "stone", "ceiling": false},
        {"op": "cuboid", "start": [3, 1, 0], "end": [3, 3, 0], "block": "air"},
        {"op": "block", "pos": [3, 5, 3], "block": "glowstone"}
      ]
    },
    {
      "name": "glass_observatory",
      "description": "A hollow glass dome on a stone cylinder base",
      "operations": [
        {"op": "cylinder", "center": [0, 0, 0], "radius": 6, "height": 6, "axis": "y", "block": "stone_bricks", "hollow": true},
        {"op": "sphere", "center": [0, 6, 0], "radius": 6, "block": "glass", "hollow": true},
        {"op": "cuboid", "start": [-5, 0, -5], "end": [5, 0, 5], "block": "polished_andesite"}
      ]
    },
    {
      "name": "pyramid",
      "description": "A solid sandstone step pyramid, 13x13 base",
      "operations": [
        {"op": "pyramid", "center": [0, 0, 0], "base": 6, "axis": "y", "block": "sandstone"}
      ]
    },
    {
      "name": "observatory_dome",
      "description": "A hollow glass dome on a stone-brick drum",
      "operations": [
        {"op": "cylinder", "center": [0, 0, 0], "radius": 6, "height": 5, "block": "stone_bricks", "hollow": true},
        {"op": "dome", "center": [0, 5, 0], "radius": 6, "block": "glass", "hollow": true}
      ]
    },
    {
      "name": "witch_tower",
      "description": "A round tower capped with a conical roof and a spire",
      "operations": [
        {"op": "cylinder", "center": [0, 0, 0], "radius": 4, "height": 12, "block": "stone_bricks", "hollow": true},
        {"op": "cone", "center": [0, 12, 0], "radius": 6, "height": 7, "block": "dark_oak_planks", "hollow": true},
        {"op": "block", "pos": [0, 19, 0], "block": "lightning_rod"}
      ]
    },
    {
      "name": "giant_egg",
      "description": "A hollow ellipsoid — a 12-tall egg you can walk inside",
      "operations": [
        {"op": "ellipsoid", "center": [0, 6, 0], "rx": 5, "ry": 7, "rz": 5, "block": "smooth_quartz", "hollow": true}
      ]
    },
    {
      "name": "fountain_ring",
      "description": "A torus ring of prismarine sitting in a pool",
      "operations": [
        {"op": "cuboid", "start": [-9, 0, -9], "end": [9, 0, 9], "block": "water"},
        {"op": "torus", "center": [0, 1, 0], "major_radius": 6, "minor_radius": 2, "block": "prismarine"}
      ]
    }
  ]
}
