{
  "name": "japanese_pagoda",
  "description": "3-tier Japanese pagoda with stone foundation, dark oak planks, slab roofs extending 1 block, and oak fence corner posts",
  "blocks": [
    {
      "x": 0,
      "y": 0,
      "z": 0,
      "block_type": "stone"
    },
    {
      "x": 0,
      "y": 0,
      "z": 1,
      "block_type": "stone"
    },
    {
      "x": 0,
      "y": 0,
      "z": 2,
      "block_type": "stone"
    },
    {
      "x": 0,
      "y": 0,
      "z": 3,
      "block_type": "stone"
    },
    {
      "x": 0,
      "y": 0,
      "z": 4,
      "block_type": "stone"
    },
    {
      "x": 0,
      "y": 0,
      "z": 5,
      "block_type": "stone"
    },
    {
      "x": 0,
      "y": 0,
      "z": 6,
      "block_type": "stone"
    },
    {
      "x": 0,
      "y": 0,
      "z": 7,
      "block_type": "stone"
    },
    {
      "x": 0,
      "y": 0,
      "z": 8,
      "block_type": "stone"
    },
    {
      "x": 0,
      "y": 0,
      "z": 9,
      "block_type": "stone"
    },
    {
      "x": 0,
      "y": 0,
      "z": 10,
      "block_type": "stone"
    },
    {
      "x": 1,
      "y": 0,
      "z": 0,
      "block_type": "stone"
    },
    {
      "x": 1,
      "y": 0,
      "z": 1,
      "block_type": "stone"
    },
    {
      "x": 1,
      "y": 0,
      "z": 2,
      "block_type": "stone"
    },
    {
      "x": 1,
      "y": 0,
      "z": 3,
      "block_type": "stone"
    },
    {
      "x": 1,
      "y": 0,
      "z": 4,
      "block_type": "stone"
    },
    {
      "x": 1,
      "y": 0,
      "z": 5,
      "block_type": "stone"
    },
    {
      "x": 1,
      "y": 0,
      "z": 6,
      "block_type": "stone"
    },
    {
      "x": 1,
      "y": 0,
      "z": 7,
      "block_type": "stone"
    },
    {
      "x": 1,
      "y": 0,
      "z": 8,
      "block_type": "stone"
    },
    {
      "x": 1,
      "y": 0,
      "z": 9,
      "block_type": "stone"
    },
    {
      "x": 1,
      "y": 0,
      "z": 10,
      "block_type": "stone"
    },
    {
      "x": 2,
      "y": 0,
      "z": 0,
      "block_type": "stone"
    },
    {
      "x": 2,
      "y": 0,
      "z": 1,
      "block_type": "stone"
    },
    {
      "x": 2,
      "y": 0,
      "z": 2,
      "block_type": "stone"
    },
    {
      "x": 2,
      "y": 0,
      "z": 3,
      "block_type": "stone"
    },
    {
      "x": 2,
      "y": 0,
      "z": 4,
      "block_type": "stone"
    },
    {
      "x": 2,
      "y": 0,
      "z": 5,
      "block_type": "stone"
    },
    {
      "x": 2,
      "y": 0,
      "z": 6,
      "block_type": "stone"
    },
    {
      "x": 2,
      "y": 0,
      "z": 7,
      "block_type": "stone"
    },
    {
      "x": 2,
      "y": 0,
      "z": 8,
      "block_type": "stone"
    },
    {
      "x": 2,
      "y": 0,
      "z": 9,
      "block_type": "stone"
    },
    {
      "x": 2,
      "y": 0,
      "z": 10,
      "block_type": "stone"
    },
    {
      "x": 3,
      "y": 0,
      "z": 0,
      "block_type": "stone"
    },
    {
      "x": 3,
      "y": 0,
      "z": 1,
      "block_type": "stone"
    },
    {
      "x": 3,
      "y": 0,
      "z": 2,
      "block_type": "stone"
    },
    {
      "x": 3,
      "y": 0,
      "z": 3,
      "block_type": "stone"
    },
    {
      "x": 3,
      "y": 0,
      "z": 4,
      "block_type": "stone"
    },
    {
      "x": 3,
      "y": 0,
      "z": 5,
      "block_type": "stone"
    },
    {
      "x": 3,
      "y": 0,
      "z": 6,
      "block_type": "stone"
    },
    {
      "x": 3,
      "y": 0,
      "z": 7,
      "block_type": "stone"
    },
    {
      "x": 3,
      "y": 0,
      "z": 8,
      "block_type": "stone"
    },
    {
      "x": 3,
      "y": 0,
      "z": 9,
      "block_type": "stone"
    },
    {
      "x": 3,
      "y": 0,
      "z": 10,
      "block_type": "stone"
    },
    {
      "x": 4,
      "y": 0,
      "z": 0,
      "block_type": "stone"
    },
    {
      "x": 4,
      "y": 0,
      "z": 1,
      "block_type": "stone"
    },
    {
      "x": 4,
      "y": 0,
      "z": 2,
      "block_type": "stone"
    },
    {
      "x": 4,
      "y": 0,
      "z": 3,
      "block_type": "stone"
    },
    {
      "x": 4,
      "y": 0,
      "z": 4,
      "block_type": "stone"
    },
    {
      "x": 4,
      "y": 0,
      "z": 5,
      "block_type": "stone"
    },
    {
      "x": 4,
      "y": 0,
      "z": 6,
      "block_type": "stone"
    },
    {
      "x": 4,
      "y": 0,
      "z": 7,
      "block_type": "stone"
    },
    {
      "x": 4,
      "y": 0,
      "z": 8,
      "block_type": "stone"
    },
    {
      "x": 4,
      "y": 0,
      "z": 9,
      "block_type": "stone"
    },
    {
      "x": 4,
      "y": 0,
      "z": 10,
      "block_type": "stone"
    },
    {
      "x": 5,
      "y": 0,
      "z": 0,
      "block_type": "stone"
    },
    {
      "x": 5,
      "y": 0,
      "z": 1,
      "block_type": "stone"
    },
    {
      "x": 5,
      "y": 0,
      "z": 2,
      "block_type": "stone"
    },
    {
      "x": 5,
      "y": 0,
      "z": 3,
      "block_type": "stone"
    },
    {
      "x": 5,
      "y": 0,
      "z": 4,
      "block_type": "stone"
    },
    {
      "x": 5,
      "y": 0,
      "z": 5,
      "block_type": "stone"
    },
    {
      "x": 5,
      "y": 0,
      "z": 6,
      "block_type": "stone"
    },
    {
      "x": 5,
      "y": 0,
      "z": 7,
      "block_type": "stone"
    },
    {
      "x": 5,
      "y": 0,
      "z": 8,
      "block_type": "stone"
    },
    {
      "x": 5,
      "y": 0,
      "z": 9,
      "block_type": "stone"
    },
    {
      "x": 5,
      "y": 0,
      "z": 10,
      "block_type": "stone"
    },
    {
      "x": 6,
      "y": 0,
      "z": 0,
      "block_type": "stone"
    },
    {
      "x": 6,
      "y": 0,
      "z": 1,
      "block_type": "stone"
    },
    {
      "x": 6,
      "y": 0,
      "z": 2,
      "block_type": "stone"
    },
    {
      "x": 6,
      "y": 0,
      "z": 3,
      "block_type": "stone"
    },
    {
      "x": 6,
      "y": 0,
      "z": 4,
      "block_type": "stone"
    },
    {
      "x": 6,
      "y": 0,
      "z": 5,
      "block_type": "stone"
    },
    {
      "x": 6,
      "y": 0,
      "z": 6,
      "block_type": "stone"
    },
    {
      "x": 6,
      "y": 0,
      "z": 7,
      "block_type": "stone"
    },
    {
      "x": 6,
      "y": 0,
      "z": 8,
      "block_type": "stone"
    },
    {
      "x": 6,
      "y": 0,
      "z": 9,
      "block_type": "stone"
    },
    {
      "x": 6,
      "y": 0,
      "z": 10,
      "block_type": "stone"
    },
    {
      "x": 7,
      "y": 0,
      "z": 0,
      "block_type": "stone"
    },
    {
      "x": 7,
      "y": 0,
      "z": 1,
      "block_type": "stone"
    },
    {
      "x": 7,
      "y": 0,
      "z": 2,
      "block_type": "stone"
    },
    {
      "x": 7,
      "y": 0,
      "z": 3,
      "block_type": "stone"
    },
    {
      "x": 7,
      "y": 0,
      "z": 4,
      "block_type": "stone"
    },
    {
      "x": 7,
      "y": 0,
      "z": 5,
      "block_type": "stone"
    },
    {
      "x": 7,
      "y": 0,
      "z": 6,
      "block_type": "stone"
    },
    {
      "x": 7,
      "y": 0,
      "z": 7,
      "block_type": "stone"
    },
    {
      "x": 7,
      "y": 0,
      "z": 8,
      "block_type": "stone"
    },
    {
      "x": 7,
      "y": 0,
      "z": 9,
      "block_type": "stone"
    },
    {
      "x": 7,
      "y": 0,
      "z": 10,
      "block_type": "stone"
    },
    {
      "x": 8,
      "y": 0,
      "z": 0,
      "block_type": "stone"
    },
    {
      "x": 8,
      "y": 0,
      "z": 1,
      "block_type": "stone"
    },
    {
      "x": 8,
      "y": 0,
      "z": 2,
      "block_type": "stone"
    },
    {
      "x": 8,
      "y": 0,
      "z": 3,
      "block_type": "stone"
    },
    {
      "x": 8,
      "y": 0,
      "z": 4,
      "block_type": "stone"
    },
    {
      "x": 8,
      "y": 0,
      "z": 5,
      "block_type": "stone"
    },
    {
      "x": 8,
      "y": 0,
      "z": 6,
      "block_type": "stone"
    },
    {
      "x": 8,
      "y": 0,
      "z": 7,
      "block_type": "stone"
    },
    {
      "x": 8,
      "y": 0,
      "z": 8,
      "block_type": "stone"
    },
    {
      "x": 8,
      "y": 0,
      "z": 9,
      "block_type": "stone"
    },
    {
      "x": 8,
      "y": 0,
      "z": 10,
      "block_type": "stone"
    },
    {
      "x": 9,
      "y": 0,
      "z": 0,
      "block_type": "stone"
    },
    {
      "x": 9,
      "y": 0,
      "z": 1,
      "block_type": "stone"
    },
    {
      "x": 9,
      "y": 0,
      "z": 2,
      "block_type": "stone"
    },
    {
      "x": 9,
      "y": 0,
      "z": 3,
      "block_type": "stone"
    },
    {
      "x": 9,
      "y": 0,
      "z": 4,
      "block_type": "stone"
    },
    {
      "x": 9,
      "y": 0,
      "z": 5,
      "block_type": "stone"
    },
    {
      "x": 9,
      "y": 0,
      "z": 6,
      "block_type": "stone"
    },
    {
      "x": 9,
      "y": 0,
      "z": 7,
      "block_type": "stone"
    },
    {
      "x": 9,
      "y": 0,
      "z": 8,
      "block_type": "stone"
    },
    {
      "x": 9,
      "y": 0,
      "z": 9,
      "block_type": "stone"
    },
    {
      "x": 9,
      "y": 0,
      "z": 10,
      "block_type": "stone"
    },
    {
      "x": 10,
      "y": 0,
      "z": 0,
      "block_type": "stone"
    },
    {
      "x": 10,
      "y": 0,
      "z": 1,
      "block_type": "stone"
    },
    {
      "x": 10,
      "y": 0,
      "z": 2,
      "block_type": "stone"
    },
    {
      "x": 10,
      "y": 0,
      "z": 3,
      "block_type": "stone"
    },
    {
      "x": 10,
      "y": 0,
      "z": 4,
      "block_type": "stone"
    },
    {
      "x": 10,
      "y": 0,
      "z": 5,
      "block_type": "stone"
    },
    {
      "x": 10,
      "y": 0,
      "z": 6,
      "block_type": "stone"
    },
    {
      "x": 10,
      "y": 0,
      "z": 7,
      "block_type": "stone"
    },
    {
      "x": 10,
      "y": 0,
      "z": 8,
      "block_type": "stone"
    },
    {
      "x": 10,
      "y": 0,
      "z": 9,
      "block_type": "stone"
    },
    {
      "x": 10,
      "y": 0,
      "z": 10,
      "block_type": "stone"
    },
    {
      "x": 0,
      "y": 1,
      "z": 0,
      "block_type": "oak_fence"
    },
    {
      "x": 0,
      "y": 1,
      "z": 1,
      "block_type": "dark_oak_planks"
    },
    {
      "x": 0,
      "y": 1,
      "z": 2,
      "block_type": "dark_oak_planks"
    },
    {
      "x": 0,
      "y": 1,
      "z": 3,
      "block_type": "dark_oak_planks"
    },
    {
      "x": 0,
      "y": 1,
      "z": 4,
      "block_type": "dark_oak_planks"
    },
    {
      "x": 0,
      "y": 1,
      "z": 5,
      "block_type": "dark_oak_planks"
    },
    {
      "x": 0,
      "y": 1,
      "z": 6,
      "block_type": "dark_oak_planks"
    },
    {
      "x": 0,
      "y": 1,
      "z": 7,
      "block_type": "dark_oak_planks"
    },
    {
      "x": 0,
      "y": 1,
      "z": 8,
      "block_type": "dark_oak_planks"
    },
    {
      "x": 0,
      "y": 1,
      "z": 9,
      "block_type": "dark_oak_planks"
    },
    {
      "x": 0,
      "y": 1,
      "z": 10,
      "block_type": "oak_fence"
    },
    {
      "x": 10,
      "y": 1,
      "z": 0,
      "block_type": "oak_fence"
    },
    {
      "x": 10,
      "y": 1,
      "z": 1,
      "block_type": "dark_oak_planks"
    },
    {
      "x": 10,
      "y": 1,
      "z": 2,
      "block_type": "dark_oak_planks"
    },
    {
      "x": 10,
      "y": 1,
      "z": 3,
      "block_type": "dark_oak_planks"
    },
    {
      "x": 10,
      "y": 1,
      "z": 4,
      "block_type": "dark_oak_planks"
    },
    {
      "x": 10,
      "y": 1,
      "z": 5,
      "block_type": "dark_oak_planks"
    },
    {
      "x": 10,
      "y": 1,
      "z": 6,
      "block_type": "dark_oak_planks"
    },
    {
      "x": 10,
      "y": 1,
      "z": 7,
      "block_type": "dark_oak_planks"
    },
    {
      "x": 10,
      "y": 1,
      "z": 8,
      "block_type": "dark_oak_planks"
    },
    {
      "x": 10,
      "y": 1,
      "z": 9,
      "block_type": "dark_oak_planks"
    },
    {
      "x": 10,
      "y": 1,
      "z": 10,
      "block_type": "oak_fence"
    },
    {
      "x": 1,
      "y": 1,
      "z": 0,
      "block_type": "dark_oak_planks"
    },
    {
      "x": 2,
      "y": 1,
      "z": 0,
      "block_type": "dark_oak_planks"
    },
    {
      "x": 3,
      "y": 1,
      "z": 0,
      "block_type": "dark_oak_planks"
    },
    {
      "x": 4,
      "y": 1,
      "z": 0,
      "block_type": "dark_oak_planks"
    },
    {
      "x": 5,
      "y": 1,
      "z": 0,
      "block_type": "dark_oak_planks"
    },
    {
      "x": 6,
      "y": 1,
      "z": 0,
      "block_type": "dark_oak_planks"
    },
    {
      "x": 7,
      "y": 1,
      "z": 0,
      "block_type": "dark_oak_planks"
    },
    {
      "x": 8,
      "y": 1,
      "z": 0,
      "block_type": "dark_oak_planks"
    },
    {
      "x": 9,
      "y": 1,
      "z": 0,
      "block_type": "dark_oak_planks"
    },
    {
      "x": 1,
      "y": 1,
      "z": 10,
      "block_type": "dark_oak_planks"
    },
    {
      "x": 2,
      "y": 1,
      "z": 10,
      "block_type": "dark_oak_planks"
    },
    {
      "x": 3,
      "y": 1,
      "z": 10,
      "block_type": "dark_oak_planks"
    },
    {
      "x": 4,
      "y": 1,
      "z": 10,
      "block_type": "dark_oak_planks"
    },
    {
      "x": 5,
      "y": 1,
      "z": 10,
      "block_type": "dark_oak_planks"
    },
    {
      "x": 6,
      "y": 1,
      "z": 10,
      "block_type": "dark_oak_planks"
    },
    {
      "x": 7,
      "y": 1,
      "z": 10,
      "block_type": "dark_oak_planks"
    },
    {
      "x": 8,
      "y": 1,
      "z": 10,
      "block_type": "dark_oak_planks"
    },
    {
      "x": 9,
      "y": 1,
      "z": 10,
      "block_type": "dark_oak_planks"
    },
    {
      "x": 0,
      "y": 2,
      "z": 0,
      "block_type": "oak_fence"
    },
    {
      "x": 0,
      "y": 2,
      "z": 1,
      "block_type": "dark_oak_planks"
    },
    {
      "x": 0,
      "y": 2,
      "z": 2,
      "block_type": "dark_oak_planks"
    },
    {
      "x": 0,
      "y": 2,
      "z": 3,
      "block_type": "dark_oak_planks"
    },
    {
      "x": 0,
      "y": 2,
      "z": 4,
      "block_type": "dark_oak_planks"
    },
    {
      "x": 0,
      "y": 2,
      "z": 5,
      "block_type": "dark_oak_planks"
    },
    {
      "x": 0,
      "y": 2,
      "z": 6,
      "block_type": "dark_oak_planks"
    },
    {
      "x": 0,
      "y": 2,
      "z": 7,
      "block_type": "dark_oak_planks"
    },
    {
      "x": 0,
      "y": 2,
      "z": 8,
      "block_type": "dark_oak_planks"
    },
    {
      "x": 0,
      "y": 2,
      "z": 9,
      "block_type": "dark_oak_planks"
    },
    {
      "x": 0,
      "y": 2,
      "z": 10,
      "block_type": "oak_fence"
    },
    {
      "x": 10,
      "y": 2,
      "z": 0,
      "block_type": "oak_fence"
    },
    {
      "x": 10,
      "y": 2,
      "z": 1,
      "block_type": "dark_oak_planks"
    },
    {
      "x": 10,
      "y": 2,
      "z": 2,
      "block_type": "dark_oak_planks"
    },
    {
      "x": 10,
      "y": 2,
      "z": 3,
      "block_type": "dark_oak_planks"
    },
    {
      "x": 10,
      "y": 2,
      "z": 4,
      "block_type": "dark_oak_planks"
    },
    {
      "x": 10,
      "y": 2,
      "z": 5,
      "block_type": "dark_oak_planks"
    },
    {
      "x": 10,
      "y": 2,
      "z": 6,
      "block_type": "dark_oak_planks"
    },
    {
      "x": 10,
      "y": 2,
      "z": 7,
      "block_type": "dark_oak_planks"
    },
    {
      "x": 10,
      "y": 2,
      "z": 8,
      "block_type": "dark_oak_planks"
    },
    {
      "x": 10,
      "y": 2,
      "z": 9,
      "block_type": "dark_oak_planks"
    },
    {
      "x": 10,
      "y": 2,
      "z": 10,
      "block_type": "oak_fence"
    },
    {
      "x": 1,
      "y": 2,
      "z": 0,
      "block_type": "dark_oak_planks"
    },
    {
      "x": 2,
      "y": 2,
      "z": 0,
      "block_type": "dark_oak_planks"
    },
    {
      "x": 3,
      "y": 2,
      "z": 0,
      "block_type": "dark_oak_planks"
    },
    {
      "x": 4,
      "y": 2,
      "z": 0,
      "block_type": "dark_oak_planks"
    },
    {
      "x": 5,
      "y": 2,
      "z": 0,
      "block_type": "dark_oak_planks"
    },
    {
      "x": 6,
      "y": 2,
      "z": 0,
      "block_type": "dark_oak_planks"
    },
    {
      "x": 7,
      "y": 2,
      "z": 0,
      "block_type": "dark_oak_planks"
    },
    {
      "x": 8,
      "y": 2,
      "z": 0,
      "block_type": "dark_oak_planks"
    },
    {
      "x": 9,
      "y": 2,
      "z": 0,
      "block_type": "dark_oak_planks"
    },
    {
      "x": 1,
      "y": 2,
      "z": 10,
      "block_type": "dark_oak_planks"
    },
    {
      "x": 2,
      "y": 2,
      "z": 10,
      "block_type": "dark_oak_planks"
    },
    {
      "x": 3,
      "y": 2,
      "z": 10,
      "block_type": "dark_oak_planks"
    },
    {
      "x": 4,
      "y": 2,
      "z": 10,
      "block_type": "dark_oak_planks"
    },
    {
      "x": 5,
      "y": 2,
      "z": 10,
      "block_type": "dark_oak_planks"
    },
    {
      "x": 6,
      "y": 2,
      "z": 10,
      "block_type": "dark_oak_planks"
    },
    {
      "x": 7,
      "y": 2,
      "z": 10,
      "block_type": "dark_oak_planks"
    },
    {
      "x": 8,
      "y": 2,
      "z": 10,
      "block_type": "dark_oak_planks"
    },
    {
      "x": 9,
      "y": 2,
      "z": 10,
      "block_type": "dark_oak_planks"
    },
    {
      "x": 0,
      "y": 3,
      "z": 0,
      "block_type": "oak_fence"
    },
    {
      "x": 0,
      "y": 3,
      "z": 1,
      "block_type": "dark_oak_planks"
    },
    {
      "x": 0,
      "y": 3,
      "z": 2,
      "block_type": "dark_oak_planks"
    },
    {
      "x": 0,
      "y": 3,
      "z": 3,
      "block_type": "dark_oak_planks"
    },
    {
      "x": 0,
      "y": 3,
      "z": 4,
      "block_type": "dark_oak_planks"
    },
    {
      "x": 0,
      "y": 3,
      "z": 5,
      "block_type": "dark_oak_planks"
    },
    {
      "x": 0,
      "y": 3,
      "z": 6,
      "block_type": "dark_oak_planks"
    },
    {
      "x": 0,
      "y": 3,
      "z": 7,
      "block_type": "dark_oak_planks"
    },
    {
      "x": 0,
      "y": 3,
      "z": 8,
      "block_type": "dark_oak_planks"
    },
    {
      "x": 0,
      "y": 3,
      "z": 9,
      "block_type": "dark_oak_planks"
    },
    {
      "x": 0,
      "y": 3,
      "z": 10,
      "block_type": "oak_fence"
    },
    {
      "x": 10,
      "y": 3,
      "z": 0,
      "block_type": "oak_fence"
    },
    {
      "x": 10,
      "y": 3,
      "z": 1,
      "block_type": "dark_oak_planks"
    },
    {
      "x": 10,
      "y": 3,
      "z": 2,
      "block_type": "dark_oak_planks"
    },
    {
      "x": 10,
      "y": 3,
      "z": 3,
      "block_type": "dark_oak_planks"
    },
    {
      "x": 10,
      "y": 3,
      "z": 4,
      "block_type": "dark_oak_planks"
    },
    {
      "x": 10,
      "y": 3,
      "z": 5,
      "block_type": "dark_oak_planks"
    },
    {
      "x": 10,
      "y": 3,
      "z": 6,
      "block_type": "dark_oak_planks"
    },
    {
      "x": 10,
      "y": 3,
      "z": 7,
      "block_type": "dark_oak_planks"
    },
    {
      "x": 10,
      "y": 3,
      "z": 8,
      "block_type": "dark_oak_planks"
    },
    {
      "x": 10,
      "y": 3,
      "z": 9,
      "block_type": "dark_oak_planks"
    },
    {
      "x": 10,
      "y": 3,
      "z": 10,
      "block_type": "oak_fence"
    },
    {
      "x": 1,
      "y": 3,
      "z": 0,
      "block_type": "dark_oak_planks"
    },
    {
      "x": 2,
      "y": 3,
      "z": 0,
      "block_type": "dark_oak_planks"
    },
    {
      "x": 3,
      "y": 3,
      "z": 0,
      "block_type": "dark_oak_planks"
    },
    {
      "x": 4,
      "y": 3,
      "z": 0,
      "block_type": "dark_oak_planks"
    },
    {
      "x": 5,
      "y": 3,
      "z": 0,
      "block_type": "dark_oak_planks"
    },
    {
      "x": 6,
      "y": 3,
      "z": 0,
      "block_type": "dark_oak_planks"
    },
    {
      "x": 7,
      "y": 3,
      "z": 0,
      "block_type": "dark_oak_planks"
    },
    {
      "x": 8,
      "y": 3,
      "z": 0,
      "block_type": "dark_oak_planks"
    },
    {
      "x": 9,
      "y": 3,
      "z": 0,
      "block_type": "dark_oak_planks"
    },
    {
      "x": 1,
      "y": 3,
      "z": 10,
      "block_type": "dark_oak_planks"
    },
    {
      "x": 2,
      "y": 3,
      "z": 10,
      "block_type": "dark_oak_planks"
    },
    {
      "x": 3,
      "y": 3,
      "z": 10,
      "block_type": "dark_oak_planks"
    },
    {
      "x": 4,
      "y": 3,
      "z": 10,
      "block_type": "dark_oak_planks"
    },
    {
      "x": 5,
      "y": 3,
      "z": 10,
      "block_type": "dark_oak_planks"
    },
    {
      "x": 6,
      "y": 3,
      "z": 10,
      "block_type": "dark_oak_planks"
    },
    {
      "x": 7,
      "y": 3,
      "z": 10,
      "block_type": "dark_oak_planks"
    },
    {
      "x": 8,
      "y": 3,
      "z": 10,
      "block_type": "dark_oak_planks"
    },
    {
      "x": 9,
      "y": 3,
      "z": 10,
      "block_type": "dark_oak_planks"
    },
    {
      "x": 0,
      "y": 4,
      "z": 0,
      "block_type": "oak_fence"
    },
    {
      "x": 0,
      "y": 4,
      "z": 1,
      "block_type": "dark_oak_planks"
    },
    {
      "x": 0,
      "y": 4,
      "z": 2,
      "block_type": "dark_oak_planks"
    },
    {
      "x": 0,
      "y": 4,
      "z": 3,
      "block_type": "dark_oak_planks"
    },
    {
      "x": 0,
      "y": 4,
      "z": 4,
      "block_type": "dark_oak_planks"
    },
    {
      "x": 0,
      "y": 4,
      "z": 5,
      "block_type": "dark_oak_planks"
    },
    {
      "x": 0,
      "y": 4,
      "z": 6,
      "block_type": "dark_oak_planks"
    },
    {
      "x": 0,
      "y": 4,
      "z": 7,
      "block_type": "dark_oak_planks"
    },
    {
      "x": 0,
      "y": 4,
      "z": 8,
      "block_type": "dark_oak_planks"
    },
    {
      "x": 0,
      "y": 4,
      "z": 9,
      "block_type": "dark_oak_planks"
    },
    {
      "x": 0,
      "y": 4,
      "z": 10,
      "block_type": "oak_fence"
    },
    {
      "x": 10,
      "y": 4,
      "z": 0,
      "block_type": "oak_fence"
    },
    {
      "x": 10,
      "y": 4,
      "z": 1,
      "block_type": "dark_oak_planks"
    },
    {
      "x": 10,
      "y": 4,
      "z": 2,
      "block_type": "dark_oak_planks"
    },
    {
      "x": 10,
      "y": 4,
      "z": 3,
      "block_type": "dark_oak_planks"
    },
    {
      "x": 10,
      "y": 4,
      "z": 4,
      "block_type": "dark_oak_planks"
    },
    {
      "x": 10,
      "y": 4,
      "z": 5,
      "block_type": "dark_oak_planks"
    },
    {
      "x": 10,
      "y": 4,
      "z": 6,
      "block_type": "dark_oak_planks"
    },
    {
      "x": 10,
      "y": 4,
      "z": 7,
      "block_type": "dark_oak_planks"
    },
    {
      "x": 10,
      "y": 4,
      "z": 8,
      "block_type": "dark_oak_planks"
    },
    {
      "x": 10,
      "y": 4,
      "z": 9,
      "block_type": "dark_oak_planks"
    },
    {
      "x": 10,
      "y": 4,
      "z": 10,
      "block_type": "oak_fence"
    },
    {
      "x": 1,
      "y": 4,
      "z": 0,
      "block_type": "dark_oak_planks"
    },
    {
      "x": 2,
      "y": 4,
      "z": 0,
      "block_type": "dark_oak_planks"
    },
    {
      "x": 3,
      "y": 4,
      "z": 0,
      "block_type": "dark_oak_planks"
    },
    {
      "x": 4,
      "y": 4,
      "z": 0,
      "block_type": "dark_oak_planks"
    },
    {
      "x": 5,
      "y": 4,
      "z": 0,
      "block_type": "dark_oak_planks"
    },
    {
      "x": 6,
      "y": 4,
      "z": 0,
      "block_type": "dark_oak_planks"
    },
    {
      "x": 7,
      "y": 4,
      "z": 0,
      "block_type": "dark_oak_planks"
    },
    {
      "x": 8,
      "y": 4,
      "z": 0,
      "block_type": "dark_oak_planks"
    },
    {
      "x": 9,
      "y": 4,
      "z": 0,
      "block_type": "dark_oak_planks"
    },
    {
      "x": 1,
      "y": 4,
      "z": 10,
      "block_type": "dark_oak_planks"
    },
    {
      "x": 2,
      "y": 4,
      "z": 10,
      "block_type": "dark_oak_planks"
    },
    {
      "x": 3,
      "y": 4,
      "z": 10,
      "block_type": "dark_oak_planks"
    },
    {
      "x": 4,
      "y": 4,
      "z": 10,
      "block_type": "dark_oak_planks"
    },
    {
      "x": 5,
      "y": 4,
      "z": 10,
      "block_type": "dark_oak_planks"
    },
    {
      "x": 6,
      "y": 4,
      "z": 10,
      "block_type": "dark_oak_planks"
    },
    {
      "x": 7,
      "y": 4,
      "z": 10,
      "block_type": "dark_oak_planks"
    },
    {
      "x": 8,
      "y": 4,
      "z": 10,
      "block_type": "dark_oak_planks"
    },
    {
      "x": 9,
      "y": 4,
      "z": 10,
      "block_type": "dark_oak_planks"
    },
    {
      "x": 0,
      "y": 5,
      "z": 0,
      "block_type": "oak_fence"
    },
    {
      "x": 0,
      "y": 5,
      "z": 1,
      "block_type": "dark_oak_planks"
    },
    {
      "x": 0,
      "y": 5,
      "z": 2,
      "block_type": "dark_oak_planks"
    },
    {
      "x": 0,
      "y": 5,
      "z": 3,
      "block_type": "dark_oak_planks"
    },
    {
      "x": 0,
      "y": 5,
      "z": 4,
      "block_type": "dark_oak_planks"
    },
    {
      "x": 0,
      "y": 5,
      "z": 5,
      "block_type": "dark_oak_planks"
    },
    {
      "x": 0,
      "y": 5,
      "z": 6,
      "block_type": "dark_oak_planks"
    },
    {
      "x": 0,
      "y": 5,
      "z": 7,
      "block_type": "dark_oak_planks"
    },
    {
      "x": 0,
      "y": 5,
      "z": 8,
      "block_type": "dark_oak_planks"
    },
    {
      "x": 0,
      "y": 5,
      "z": 9,
      "block_type": "dark_oak_planks"
    },
    {
      "x": 0,
      "y": 5,
      "z": 10,
      "block_type": "oak_fence"
    },
    {
      "x": 10,
      "y": 5,
      "z": 0,
      "block_type": "oak_fence"
    },
    {
      "x": 10,
      "y": 5,
      "z": 1,
      "block_type": "dark_oak_planks"
    },
    {
      "x": 10,
      "y": 5,
      "z": 2,
      "block_type": "dark_oak_planks"
    },
    {
      "x": 10,
      "y": 5,
      "z": 3,
      "block_type": "dark_oak_planks"
    },
    {
      "x": 10,
      "y": 5,
      "z": 4,
      "block_type": "dark_oak_planks"
    },
    {
      "x": 10,
      "y": 5,
      "z": 5,
      "block_type": "dark_oak_planks"
    },
    {
      "x": 10,
      "y": 5,
      "z": 6,
      "block_type": "dark_oak_planks"
    },
    {
      "x": 10,
      "y": 5,
      "z": 7,
      "block_type": "dark_oak_planks"
    },
    {
      "x": 10,
      "y": 5,
      "z": 8,
      "block_type": "dark_oak_planks"
    },
    {
      "x": 10,
      "y": 5,
      "z": 9,
      "block_type": "dark_oak_planks"
    },
    {
      "x": 10,
      "y": 5,
      "z": 10,
      "block_type": "oak_fence"
    },
    {
      "x": 1,
      "y": 5,
      "z": 0,
      "block_type": "dark_oak_planks"
    },
    {
      "x": 2,
      "y": 5,
      "z": 0,
      "block_type": "dark_oak_planks"
    },
    {
      "x": 3,
      "y": 5,
      "z": 0,
      "block_type": "dark_oak_planks"
    },
    {
      "x": 4,
      "y": 5,
      "z": 0,
      "block_type": "dark_oak_planks"
    },
    {
      "x": 5,
      "y": 5,
      "z": 0,
      "block_type": "dark_oak_planks"
    },
    {
      "x": 6,
      "y": 5,
      "z": 0,
      "block_type": "dark_oak_planks"
    },
    {
      "x": 7,
      "y": 5,
      "z": 0,
      "block_type": "dark_oak_planks"
    },
    {
      "x": 8,
      "y": 5,
      "z": 0,
      "block_type": "dark_oak_planks"
    },
    {
      "x": 9,
      "y": 5,
      "z": 0,
      "block_type": "dark_oak_planks"
    },
    {
      "x": 1,
      "y": 5,
      "z": 10,
      "block_type": "dark_oak_planks"
    },
    {
      "x": 2,
      "y": 5,
      "z": 10,
      "block_type": "dark_oak_planks"
    },
    {
      "x": 3,
      "y": 5,
      "z": 10,
      "block_type": "dark_oak_planks"
    },
    {
      "x": 4,
      "y": 5,
      "z": 10,
      "block_type": "dark_oak_planks"
    },
    {
      "x": 5,
      "y": 5,
      "z": 10,
      "block_type": "dark_oak_planks"
    },
    {
      "x": 6,
      "y": 5,
      "z": 10,
      "block_type": "dark_oak_planks"
    },
    {
      "x": 7,
      "y": 5,
      "z": 10,
      "block_type": "dark_oak_planks"
    },
    {
      "x": 8,
      "y": 5,
      "z": 10,
      "block_type": "dark_oak_planks"
    },
    {
      "x": 9,
      "y": 5,
      "z": 10,
      "block_type": "dark_oak_planks"
    },
    {
      "x": 0,
      "y": 6,
      "z": 0,
      "block_type": "oak_fence"
    },
    {
      "x": 0,
      "y": 6,
      "z": 1,
      "block_type": "dark_oak_planks"
    },
    {
      "x": 0,
      "y": 6,
      "z": 2,
      "block_type": "dark_oak_planks"
    },
    {
      "x": 0,
      "y": 6,
      "z": 3,
      "block_type": "dark_oak_planks"
    },
    {
      "x": 0,
      "y": 6,
      "z": 4,
      "block_type": "dark_oak_planks"
    },
    {
      "x": 0,
      "y": 6,
      "z": 5,
      "block_type": "dark_oak_planks"
    },
    {
      "x": 0,
      "y": 6,
      "z": 6,
      "block_type": "dark_oak_planks"
    },
    {
      "x": 0,
      "y": 6,
      "z": 7,
      "block_type": "dark_oak_planks"
    },
    {
      "x": 0,
      "y": 6,
      "z": 8,
      "block_type": "dark_oak_planks"
    },
    {
      "x": 0,
      "y": 6,
      "z": 9,
      "block_type": "dark_oak_planks"
    },
    {
      "x": 0,
      "y": 6,
      "z": 10,
      "block_type": "oak_fence"
    },
    {
      "x": 10,
      "y": 6,
      "z": 0,
      "block_type": "oak_fence"
    },
    {
      "x": 10,
      "y": 6,
      "z": 1,
      "block_type": "dark_oak_planks"
    },
    {
      "x": 10,
      "y": 6,
      "z": 2,
      "block_type": "dark_oak_planks"
    },
    {
      "x": 10,
      "y": 6,
      "z": 3,
      "block_type": "dark_oak_planks"
    },
    {
      "x": 10,
      "y": 6,
      "z": 4,
      "block_type": "dark_oak_planks"
    },
    {
      "x": 10,
      "y": 6,
      "z": 5,
      "block_type": "dark_oak_planks"
    },
    {
      "x": 10,
      "y": 6,
      "z": 6,
      "block_type": "dark_oak_planks"
    },
    {
      "x": 10,
      "y": 6,
      "z": 7,
      "block_type": "dark_oak_planks"
    },
    {
      "x": 10,
      "y": 6,
      "z": 8,
      "block_type": "dark_oak_planks"
    },
    {
      "x": 10,
      "y": 6,
      "z": 9,
      "block_type": "dark_oak_planks"
    },
    {
      "x": 10,
      "y": 6,
      "z": 10,
      "block_type": "oak_fence"
    },
    {
      "x": 1,
      "y": 6,
      "z": 0,
      "block_type": "dark_oak_planks"
    },
    {
      "x": 2,
      "y": 6,
      "z": 0,
      "block_type": "dark_oak_planks"
    },
    {
      "x": 3,
      "y": 6,
      "z": 0,
      "block_type": "dark_oak_planks"
    },
    {
      "x": 4,
      "y": 6,
      "z": 0,
      "block_type": "dark_oak_planks"
    },
    {
      "x": 5,
      "y": 6,
      "z": 0,
      "block_type": "dark_oak_planks"
    },
    {
      "x": 6,
      "y": 6,
      "z": 0,
      "block_type": "dark_oak_planks"
    },
    {
      "x": 7,
      "y": 6,
      "z": 0,
      "block_type": "dark_oak_planks"
    },
    {
      "x": 8,
      "y": 6,
      "z": 0,
      "block_type": "dark_oak_planks"
    },
    {
      "x": 9,
      "y": 6,
      "z": 0,
      "block_type": "dark_oak_planks"
    },
    {
      "x": 1,
      "y": 6,
      "z": 10,
      "block_type": "dark_oak_planks"
    },
    {
      "x": 2,
      "y": 6,
      "z": 10,
      "block_type": "dark_oak_planks"
    },
    {
      "x": 3,
      "y": 6,
      "z": 10,
      "block_type": "dark_oak_planks"
    },
    {
      "x": 4,
      "y": 6,
      "z": 10,
      "block_type": "dark_oak_planks"
    },
    {
      "x": 5,
      "y": 6,
      "z": 10,
      "block_type": "dark_oak_planks"
    },
    {
      "x": 6,
      "y": 6,
      "z": 10,
      "block_type": "dark_oak_planks"
    },
    {
      "x": 7,
      "y": 6,
      "z": 10,
      "block_type": "dark_oak_planks"
    },
    {
      "x": 8,
      "y": 6,
      "z": 10,
      "block_type": "dark_oak_planks"
    },
    {
      "x": 9,
      "y": 6,
      "z": 10,
      "block_type": "dark_oak_planks"
    },
    {
      "x": -1,
      "y": 7,
      "z": -1,
      "block_type": "dark_oak_slab"
    },
    {
      "x": -1,
      "y": 7,
      "z": 11,
      "block_type": "dark_oak_slab"
    },
    {
      "x": 0,
      "y": 7,
      "z": -1,
      "block_type": "dark_oak_slab"
    },
    {
      "x": 0,
      "y": 7,
      "z": 11,
      "block_type": "dark_oak_slab"
    },
    {
      "x": 1,
      "y": 7,
      "z": -1,
      "block_type": "dark_oak_slab"
    },
    {
      "x": 1,
      "y": 7,
      "z": 11,
      "block_type": "dark_oak_slab"
    },
    {
      "x": 2,
      "y": 7,
      "z": -1,
      "block_type": "dark_oak_slab"
    },
    {
      "x": 2,
      "y": 7,
      "z": 11,
      "block_type": "dark_oak_slab"
    },
    {
      "x": 3,
      "y": 7,
      "z": -1,
      "block_type": "dark_oak_slab"
    },
    {
      "x": 3,
      "y": 7,
      "z": 11,
      "block_type": "dark_oak_slab"
    },
    {
      "x": 4,
      "y": 7,
      "z": -1,
      "block_type": "dark_oak_slab"
    },
    {
      "x": 4,
      "y": 7,
      "z": 11,
      "block_type": "dark_oak_slab"
    },
    {
      "x": 5,
      "y": 7,
      "z": -1,
      "block_type": "dark_oak_slab"
    },
    {
      "x": 5,
      "y": 7,
      "z": 11,
      "block_type": "dark_oak_slab"
    },
    {
      "x": 6,
      "y": 7,
      "z": -1,
      "block_type": "dark_oak_slab"
    },
    {
      "x": 6,
      "y": 7,
      "z": 11,
      "block_type": "dark_oak_slab"
    },
    {
      "x": 7,
      "y": 7,
      "z": -1,
      "block_type": "dark_oak_slab"
    },
    {
      "x": 7,
      "y": 7,
      "z": 11,
      "block_type": "dark_oak_slab"
    },
    {
      "x": 8,
      "y": 7,
      "z": -1,
      "block_type": "dark_oak_slab"
    },
    {
      "x": 8,
      "y": 7,
      "z": 11,
      "block_type": "dark_oak_slab"
    },
    {
      "x": 9,
      "y": 7,
      "z": -1,
      "block_type": "dark_oak_slab"
    },
    {
      "x": 9,
      "y": 7,
      "z": 11,
      "block_type": "dark_oak_slab"
    },
    {
      "x": 10,
      "y": 7,
      "z": -1,
      "block_type": "dark_oak_slab"
    },
    {
      "x": 10,
      "y": 7,
      "z": 11,
      "block_type": "dark_oak_slab"
    },
    {
      "x": 11,
      "y": 7,
      "z": -1,
      "block_type": "dark_oak_slab"
    },
    {
      "x": 11,
      "y": 7,
      "z": 11,
      "block_type": "dark_oak_slab"
    },
    {
      "x": -1,
      "y": 7,
      "z": 0,
      "block_type": "dark_oak_slab"
    },
    {
      "x": 11,
      "y": 7,
      "z": 0,
      "block_type": "dark_oak_slab"
    },
    {
      "x": -1,
      "y": 7,
      "z": 1,
      "block_type": "dark_oak_slab"
    },
    {
      "x": 11,
      "y": 7,
      "z": 1,
      "block_type": "dark_oak_slab"
    },
    {
      "x": -1,
      "y": 7,
      "z": 2,
      "block_type": "dark_oak_slab"
    },
    {
      "x": 11,
      "y": 7,
      "z": 2,
      "block_type": "dark_oak_slab"
    },
    {
      "x": -1,
      "y": 7,
      "z": 3,
      "block_type": "dark_oak_slab"
    },
    {
      "x": 11,
      "y": 7,
      "z": 3,
      "block_type": "dark_oak_slab"
    },
    {
      "x": -1,
      "y": 7,
      "z": 4,
      "block_type": "dark_oak_slab"
    },
    {
      "x": 11,
      "y": 7,
      "z": 4,
      "block_type": "dark_oak_slab"
    },
    {
      "x": -1,
      "y": 7,
      "z": 5,
      "block_type": "dark_oak_slab"
    },
    {
      "x": 11,
      "y": 7,
      "z": 5,
      "block_type": "dark_oak_slab"
    },
    {
      "x": -1,
      "y": 7,
      "z": 6,
      "block_type": "dark_oak_slab"
    },
    {
      "x": 11,
      "y": 7,
      "z": 6,
      "block_type": "dark_oak_slab"
    },
    {
      "x": -1,
      "y": 7,
      "z": 7,
      "block_type": "dark_oak_slab"
    },
    {
      "x": 11,
      "y": 7,
      "z": 7,
      "block_type": "dark_oak_slab"
    },
    {
      "x": -1,
      "y": 7,
      "z": 8,
      "block_type": "dark_oak_slab"
    },
    {
      "x": 11,
      "y": 7,
      "z": 8,
      "block_type": "dark_oak_slab"
    },
    {
      "x": -1,
      "y": 7,
      "z": 9,
      "block_type": "dark_oak_slab"
    },
    {
      "x": 11,
      "y": 7,
      "z": 9,
      "block_type": "dark_oak_slab"
    },
    {
      "x": -1,
      "y": 7,
      "z": 10,
      "block_type": "dark_oak_slab"
    },
    {
      "x": 11,
      "y": 7,
      "z": 10,
      "block_type": "dark_oak_slab"
    },
    {
      "x": 1,
      "y": 7,
      "z": 1,
      "block_type": "oak_fence"
    },
    {
      "x": 1,
      "y": 7,
      "z": 2,
      "block_type": "dark_oak_planks"
    },
    {
      "x": 1,
      "y": 7,
      "z": 3,
      "block_type": "dark_oak_planks"
    },
    {
      "x": 1,
      "y": 7,
      "z": 4,
      "block_type": "dark_oak_planks"
    },
    {
      "x": 1,
      "y": 7,
      "z": 5,
      "block_type": "dark_oak_planks"
    },
    {
      "x": 1,
      "y": 7,
      "z": 6,
      "block_type": "dark_oak_planks"
    },
    {
      "x": 1,
      "y": 7,
      "z": 7,
      "block_type": "dark_oak_planks"
    },
    {
      "x": 1,
      "y": 7,
      "z": 8,
      "block_type": "dark_oak_planks"
    },
    {
      "x": 1,
      "y": 7,
      "z": 9,
      "block_type": "oak_fence"
    },
    {
      "x": 9,
      "y": 7,
      "z": 1,
      "block_type": "oak_fence"
    },
    {
      "x": 9,
      "y": 7,
      "z": 2,
      "block_type": "dark_oak_planks"
    },
    {
      "x": 9,
      "y": 7,
      "z": 3,
      "block_type": "dark_oak_planks"
    },
    {
      "x": 9,
      "y": 7,
      "z": 4,
      "block_type": "dark_oak_planks"
    },
    {
      "x": 9,
      "y": 7,
      "z": 5,
      "block_type": "dark_oak_planks"
    },
    {
      "x": 9,
      "y": 7,
      "z": 6,
      "block_type": "dark_oak_planks"
    },
    {
      "x": 9,
      "y": 7,
      "z": 7,
      "block_type": "dark_oak_planks"
    },
    {
      "x": 9,
      "y": 7,
      "z": 8,
      "block_type": "dark_oak_planks"
    },
    {
      "x": 9,
      "y": 7,
      "z": 9,
      "block_type": "oak_fence"
    },
    {
      "x": 2,
      "y": 7,
      "z": 1,
      "block_type": "dark_oak_planks"
    },
    {
      "x": 3,
      "y": 7,
      "z": 1,
      "block_type": "dark_oak_planks"
    },
    {
      "x": 4,
      "y": 7,
      "z": 1,
      "block_type": "dark_oak_planks"
    },
    {
      "x": 5,
      "y": 7,
      "z": 1,
      "block_type": "dark_oak_planks"
    },
    {
      "x": 6,
      "y": 7,
      "z": 1,
      "block_type": "dark_oak_planks"
    },
    {
      "x": 7,
      "y": 7,
      "z": 1,
      "block_type": "dark_oak_planks"
    },
    {
      "x": 8,
      "y": 7,
      "z": 1,
      "block_type": "dark_oak_planks"
    },
    {
      "x": 2,
      "y": 7,
      "z": 9,
      "block_type": "dark_oak_planks"
    },
    {
      "x": 3,
      "y": 7,
      "z": 9,
      "block_type": "dark_oak_planks"
    },
    {
      "x": 4,
      "y": 7,
      "z": 9,
      "block_type": "dark_oak_planks"
    },
    {
      "x": 5,
      "y": 7,
      "z": 9,
      "block_type": "dark_oak_planks"
    },
    {
      "x": 6,
      "y": 7,
      "z": 9,
      "block_type": "dark_oak_planks"
    },
    {
      "x": 7,
      "y": 7,
      "z": 9,
      "block_type": "dark_oak_planks"
    },
    {
      "x": 8,
      "y": 7,
      "z": 9,
      "block_type": "dark_oak_planks"
    },
    {
      "x": 1,
      "y": 8,
      "z": 1,
      "block_type": "oak_fence"
    },
    {
      "x": 1,
      "y": 8,
      "z": 2,
      "block_type": "dark_oak_planks"
    },
    {
      "x": 1,
      "y": 8,
      "z": 3,
      "block_type": "dark_oak_planks"
    },
    {
      "x": 1,
      "y": 8,
      "z": 4,
      "block_type": "dark_oak_planks"
    },
    {
      "x": 1,
      "y": 8,
      "z": 5,
      "block_type": "dark_oak_planks"
    },
    {
      "x": 1,
      "y": 8,
      "z": 6,
      "block_type": "dark_oak_planks"
    },
    {
      "x": 1,
      "y": 8,
      "z": 7,
      "block_type": "dark_oak_planks"
    },
    {
      "x": 1,
      "y": 8,
      "z": 8,
      "block_type": "dark_oak_planks"
    },
    {
      "x": 1,
      "y": 8,
      "z": 9,
      "block_type": "oak_fence"
    },
    {
      "x": 9,
      "y": 8,
      "z": 1,
      "block_type": "oak_fence"
    },
    {
      "x": 9,
      "y": 8,
      "z": 2,
      "block_type": "dark_oak_planks"
    },
    {
      "x": 9,
      "y": 8,
      "z": 3,
      "block_type": "dark_oak_planks"
    },
    {
      "x": 9,
      "y": 8,
      "z": 4,
      "block_type": "dark_oak_planks"
    },
    {
      "x": 9,
      "y": 8,
      "z": 5,
      "block_type": "dark_oak_planks"
    },
    {
      "x": 9,
      "y": 8,
      "z": 6,
      "block_type": "dark_oak_planks"
    },
    {
      "x": 9,
      "y": 8,
      "z": 7,
      "block_type": "dark_oak_planks"
    },
    {
      "x": 9,
      "y": 8,
      "z": 8,
      "block_type": "dark_oak_planks"
    },
    {
      "x": 9,
      "y": 8,
      "z": 9,
      "block_type": "oak_fence"
    },
    {
      "x": 2,
      "y": 8,
      "z": 1,
      "block_type": "dark_oak_planks"
    },
    {
      "x": 3,
      "y": 8,
      "z": 1,
      "block_type": "dark_oak_planks"
    },
    {
      "x": 4,
      "y": 8,
      "z": 1,
      "block_type": "dark_oak_planks"
    },
    {
      "x": 5,
      "y": 8,
      "z": 1,
      "block_type": "dark_oak_planks"
    },
    {
      "x": 6,
      "y": 8,
      "z": 1,
      "block_type": "dark_oak_planks"
    },
    {
      "x": 7,
      "y": 8,
      "z": 1,
      "block_type": "dark_oak_planks"
    },
    {
      "x": 8,
      "y": 8,
      "z": 1,
      "block_type": "dark_oak_planks"
    },
    {
      "x": 2,
      "y": 8,
      "z": 9,
      "block_type": "dark_oak_planks"
    },
    {
      "x": 3,
      "y": 8,
      "z": 9,
      "block_type": "dark_oak_planks"
    },
    {
      "x": 4,
      "y": 8,
      "z": 9,
      "block_type": "dark_oak_planks"
    },
    {
      "x": 5,
      "y": 8,
      "z": 9,
      "block_type": "dark_oak_planks"
    },
    {
      "x": 6,
      "y": 8,
      "z": 9,
      "block_type": "dark_oak_planks"
    },
    {
      "x": 7,
      "y": 8,
      "z": 9,
      "block_type": "dark_oak_planks"
    },
    {
      "x": 8,
      "y": 8,
      "z": 9,
      "block_type": "dark_oak_planks"
    },
    {
      "x": 1,
      "y": 9,
      "z": 1,
      "block_type": "oak_fence"
    },
    {
      "x": 1,
      "y": 9,
      "z": 2,
      "block_type": "dark_oak_planks"
    },
    {
      "x": 1,
      "y": 9,
      "z": 3,
      "block_type": "dark_oak_planks"
    },
    {
      "x": 1,
      "y": 9,
      "z": 4,
      "block_type": "dark_oak_planks"
    },
    {
      "x": 1,
      "y": 9,
      "z": 5,
      "block_type": "dark_oak_planks"
    },
    {
      "x": 1,
      "y": 9,
      "z": 6,
      "block_type": "dark_oak_planks"
    },
    {
      "x": 1,
      "y": 9,
      "z": 7,
      "block_type": "dark_oak_planks"
    },
    {
      "x": 1,
      "y": 9,
      "z": 8,
      "block_type": "dark_oak_planks"
    },
    {
      "x": 1,
      "y": 9,
      "z": 9,
      "block_type": "oak_fence"
    },
    {
      "x": 9,
      "y": 9,
      "z": 1,
      "block_type": "oak_fence"
    },
    {
      "x": 9,
      "y": 9,
      "z": 2,
      "block_type": "dark_oak_planks"
    },
    {
      "x": 9,
      "y": 9,
      "z": 3,
      "block_type": "dark_oak_planks"
    },
    {
      "x": 9,
      "y": 9,
      "z": 4,
      "block_type": "dark_oak_planks"
    },
    {
      "x": 9,
      "y": 9,
      "z": 5,
      "block_type": "dark_oak_planks"
    },
    {
      "x": 9,
      "y": 9,
      "z": 6,
      "block_type": "dark_oak_planks"
    },
    {
      "x": 9,
      "y": 9,
      "z": 7,
      "block_type": "dark_oak_planks"
    },
    {
      "x": 9,
      "y": 9,
      "z": 8,
      "block_type": "dark_oak_planks"
    },
    {
      "x": 9,
      "y": 9,
      "z": 9,
      "block_type": "oak_fence"
    },
    {
      "x": 2,
      "y": 9,
      "z": 1,
      "block_type": "dark_oak_planks"
    },
    {
      "x": 3,
      "y": 9,
      "z": 1,
      "block_type": "dark_oak_planks"
    },
    {
      "x": 4,
      "y": 9,
      "z": 1,
      "block_type": "dark_oak_planks"
    },
    {
      "x": 5,
      "y": 9,
      "z": 1,
      "block_type": "dark_oak_planks"
    },
    {
      "x": 6,
      "y": 9,
      "z": 1,
      "block_type": "dark_oak_planks"
    },
    {
      "x": 7,
      "y": 9,
      "z": 1,
      "block_type": "dark_oak_planks"
    },
    {
      "x": 8,
      "y": 9,
      "z": 1,
      "block_type": "dark_oak_planks"
    },
    {
      "x": 2,
      "y": 9,
      "z": 9,
      "block_type": "dark_oak_planks"
    },
    {
      "x": 3,
      "y": 9,
      "z": 9,
      "block_type": "dark_oak_planks"
    },
    {
      "x": 4,
      "y": 9,
      "z": 9,
      "block_type": "dark_oak_planks"
    },
    {
      "x": 5,
      "y": 9,
      "z": 9,
      "block_type": "dark_oak_planks"
    },
    {
      "x": 6,
      "y": 9,
      "z": 9,
      "block_type": "dark_oak_planks"
    },
    {
      "x": 7,
      "y": 9,
      "z": 9,
      "block_type": "dark_oak_planks"
    },
    {
      "x": 8,
      "y": 9,
      "z": 9,
      "block_type": "dark_oak_planks"
    },
    {
      "x": 1,
      "y": 10,
      "z": 1,
      "block_type": "oak_fence"
    },
    {
      "x": 1,
      "y": 10,
      "z": 2,
      "block_type": "dark_oak_planks"
    },
    {
      "x": 1,
      "y": 10,
      "z": 3,
      "block_type": "dark_oak_planks"
    },
    {
      "x": 1,
      "y": 10,
      "z": 4,
      "block_type": "dark_oak_planks"
    },
    {
      "x": 1,
      "y": 10,
      "z": 5,
      "block_type": "dark_oak_planks"
    },
    {
      "x": 1,
      "y": 10,
      "z": 6,
      "block_type": "dark_oak_planks"
    },
    {
      "x": 1,
      "y": 10,
      "z": 7,
      "block_type": "dark_oak_planks"
    },
    {
      "x": 1,
      "y": 10,
      "z": 8,
      "block_type": "dark_oak_planks"
    },
    {
      "x": 1,
      "y": 10,
      "z": 9,
      "block_type": "oak_fence"
    },
    {
      "x": 9,
      "y": 10,
      "z": 1,
      "block_type": "oak_fence"
    },
    {
      "x": 9,
      "y": 10,
      "z": 2,
      "block_type": "dark_oak_planks"
    },
    {
      "x": 9,
      "y": 10,
      "z": 3,
      "block_type": "dark_oak_planks"
    },
    {
      "x": 9,
      "y": 10,
      "z": 4,
      "block_type": "dark_oak_planks"
    },
    {
      "x": 9,
      "y": 10,
      "z": 5,
      "block_type": "dark_oak_planks"
    },
    {
      "x": 9,
      "y": 10,
      "z": 6,
      "block_type": "dark_oak_planks"
    },
    {
      "x": 9,
      "y": 10,
      "z": 7,
      "block_type": "dark_oak_planks"
    },
    {
      "x": 9,
      "y": 10,
      "z": 8,
      "block_type": "dark_oak_planks"
    },
    {
      "x": 9,
      "y": 10,
      "z": 9,
      "block_type": "oak_fence"
    },
    {
      "x": 2,
      "y": 10,
      "z": 1,
      "block_type": "dark_oak_planks"
    },
    {
      "x": 3,
      "y": 10,
      "z": 1,
      "block_type": "dark_oak_planks"
    },
    {
      "x": 4,
      "y": 10,
      "z": 1,
      "block_type": "dark_oak_planks"
    },
    {
      "x": 5,
      "y": 10,
      "z": 1,
      "block_type": "dark_oak_planks"
    },
    {
      "x": 6,
      "y": 10,
      "z": 1,
      "block_type": "dark_oak_planks"
    },
    {
      "x": 7,
      "y": 10,
      "z": 1,
      "block_type": "dark_oak_planks"
    },
    {
      "x": 8,
      "y": 10,
      "z": 1,
      "block_type": "dark_oak_planks"
    },
    {
      "x": 2,
      "y": 10,
      "z": 9,
      "block_type": "dark_oak_planks"
    },
    {
      "x": 3,
      "y": 10,
      "z": 9,
      "block_type": "dark_oak_planks"
    },
    {
      "x": 4,
      "y": 10,
      "z": 9,
      "block_type": "dark_oak_planks"
    },
    {
      "x": 5,
      "y": 10,
      "z": 9,
      "block_type": "dark_oak_planks"
    },
    {
      "x": 6,
      "y": 10,
      "z": 9,
      "block_type": "dark_oak_planks"
    },
    {
      "x": 7,
      "y": 10,
      "z": 9,
      "block_type": "dark_oak_planks"
    },
    {
      "x": 8,
      "y": 10,
      "z": 9,
      "block_type": "dark_oak_planks"
    },
    {
      "x": 1,
      "y": 11,
      "z": 1,
      "block_type": "oak_fence"
    },
    {
      "x": 1,
      "y": 11,
      "z": 2,
      "block_type": "dark_oak_planks"
    },
    {
      "x": 1,
      "y": 11,
      "z": 3,
      "block_type": "dark_oak_planks"
    },
    {
      "x": 1,
      "y": 11,
      "z": 4,
      "block_type": "dark_oak_planks"
    },
    {
      "x": 1,
      "y": 11,
      "z": 5,
      "block_type": "dark_oak_planks"
    },
    {
      "x": 1,
      "y": 11,
      "z": 6,
      "block_type": "dark_oak_planks"
    },
    {
      "x": 1,
      "y": 11,
      "z": 7,
      "block_type": "dark_oak_planks"
    },
    {
      "x": 1,
      "y": 11,
      "z": 8,
      "block_type": "dark_oak_planks"
    },
    {
      "x": 1,
      "y": 11,
      "z": 9,
      "block_type": "oak_fence"
    },
    {
      "x": 9,
      "y": 11,
      "z": 1,
      "block_type": "oak_fence"
    },
    {
      "x": 9,
      "y": 11,
      "z": 2,
      "block_type": "dark_oak_planks"
    },
    {
      "x": 9,
      "y": 11,
      "z": 3,
      "block_type": "dark_oak_planks"
    },
    {
      "x": 9,
      "y": 11,
      "z": 4,
      "block_type": "dark_oak_planks"
    },
    {
      "x": 9,
      "y": 11,
      "z": 5,
      "block_type": "dark_oak_planks"
    },
    {
      "x": 9,
      "y": 11,
      "z": 6,
      "block_type": "dark_oak_planks"
    },
    {
      "x": 9,
      "y": 11,
      "z": 7,
      "block_type": "dark_oak_planks"
    },
    {
      "x": 9,
      "y": 11,
      "z": 8,
      "block_type": "dark_oak_planks"
    },
    {
      "x": 9,
      "y": 11,
      "z": 9,
      "block_type": "oak_fence"
    },
    {
      "x": 2,
      "y": 11,
      "z": 1,
      "block_type": "dark_oak_planks"
    },
    {
      "x": 3,
      "y": 11,
      "z": 1,
      "block_type": "dark_oak_planks"
    },
    {
      "x": 4,
      "y": 11,
      "z": 1,
      "block_type": "dark_oak_planks"
    },
    {
      "x": 5,
      "y": 11,
      "z": 1,
      "block_type": "dark_oak_planks"
    },
    {
      "x": 6,
      "y": 11,
      "z": 1,
      "block_type": "dark_oak_planks"
    },
    {
      "x": 7,
      "y": 11,
      "z": 1,
      "block_type": "dark_oak_planks"
    },
    {
      "x": 8,
      "y": 11,
      "z": 1,
      "block_type": "dark_oak_planks"
    },
    {
      "x": 2,
      "y": 11,
      "z": 9,
      "block_type": "dark_oak_planks"
    },
    {
      "x": 3,
      "y": 11,
      "z": 9,
      "block_type": "dark_oak_planks"
    },
    {
      "x": 4,
      "y": 11,
      "z": 9,
      "block_type": "dark_oak_planks"
    },
    {
      "x": 5,
      "y": 11,
      "z": 9,
      "block_type": "dark_oak_planks"
    },
    {
      "x": 6,
      "y": 11,
      "z": 9,
      "block_type": "dark_oak_planks"
    },
    {
      "x": 7,
      "y": 11,
      "z": 9,
      "block_type": "dark_oak_planks"
    },
    {
      "x": 8,
      "y": 11,
      "z": 9,
      "block_type": "dark_oak_planks"
    },
    {
      "x": 0,
      "y": 12,
      "z": 0,
      "block_type": "dark_oak_slab"
    },
    {
      "x": 0,
      "y": 12,
      "z": 10,
      "block_type": "dark_oak_slab"
    },
    {
      "x": 1,
      "y": 12,
      "z": 0,
      "block_type": "dark_oak_slab"
    },
    {
      "x": 1,
      "y": 12,
      "z": 10,
      "block_type": "dark_oak_slab"
    },
    {
      "x": 2,
      "y": 12,
      "z": 0,
      "block_type": "dark_oak_slab"
    },
    {
      "x": 2,
      "y": 12,
      "z": 10,
      "block_type": "dark_oak_slab"
    },
    {
      "x": 3,
      "y": 12,
      "z": 0,
      "block_type": "dark_oak_slab"
    },
    {
      "x": 3,
      "y": 12,
      "z": 10,
      "block_type": "dark_oak_slab"
    },
    {
      "x": 4,
      "y": 12,
      "z": 0,
      "block_type": "dark_oak_slab"
    },
    {
      "x": 4,
      "y": 12,
      "z": 10,
      "block_type": "dark_oak_slab"
    },
    {
      "x": 5,
      "y": 12,
      "z": 0,
      "block_type": "dark_oak_slab"
    },
    {
      "x": 5,
      "y": 12,
      "z": 10,
      "block_type": "dark_oak_slab"
    },
    {
      "x": 6,
      "y": 12,
      "z": 0,
      "block_type": "dark_oak_slab"
    },
    {
      "x": 6,
      "y": 12,
      "z": 10,
      "block_type": "dark_oak_slab"
    },
    {
      "x": 7,
      "y": 12,
      "z": 0,
      "block_type": "dark_oak_slab"
    },
    {
      "x": 7,
      "y": 12,
      "z": 10,
      "block_type": "dark_oak_slab"
    },
    {
      "x": 8,
      "y": 12,
      "z": 0,
      "block_type": "dark_oak_slab"
    },
    {
      "x": 8,
      "y": 12,
      "z": 10,
      "block_type": "dark_oak_slab"
    },
    {
      "x": 9,
      "y": 12,
      "z": 0,
      "block_type": "dark_oak_slab"
    },
    {
      "x": 9,
      "y": 12,
      "z": 10,
      "block_type": "dark_oak_slab"
    },
    {
      "x": 10,
      "y": 12,
      "z": 0,
      "block_type": "dark_oak_slab"
    },
    {
      "x": 10,
      "y": 12,
      "z": 10,
      "block_type": "dark_oak_slab"
    },
    {
      "x": 0,
      "y": 12,
      "z": 1,
      "block_type": "dark_oak_slab"
    },
    {
      "x": 10,
      "y": 12,
      "z": 1,
      "block_type": "dark_oak_slab"
    },
    {
      "x": 0,
      "y": 12,
      "z": 2,
      "block_type": "dark_oak_slab"
    },
    {
      "x": 10,
      "y": 12,
      "z": 2,
      "block_type": "dark_oak_slab"
    },
    {
      "x": 0,
      "y": 12,
      "z": 3,
      "block_type": "dark_oak_slab"
    },
    {
      "x": 10,
      "y": 12,
      "z": 3,
      "block_type": "dark_oak_slab"
    },
    {
      "x": 0,
      "y": 12,
      "z": 4,
      "block_type": "dark_oak_slab"
    },
    {
      "x": 10,
      "y": 12,
      "z": 4,
      "block_type": "dark_oak_slab"
    },
    {
      "x": 0,
      "y": 12,
      "z": 5,
      "block_type": "dark_oak_slab"
    },
    {
      "x": 10,
      "y": 12,
      "z": 5,
      "block_type": "dark_oak_slab"
    },
    {
      "x": 0,
      "y": 12,
      "z": 6,
      "block_type": "dark_oak_slab"
    },
    {
      "x": 10,
      "y": 12,
      "z": 6,
      "block_type": "dark_oak_slab"
    },
    {
      "x": 0,
      "y": 12,
      "z": 7,
      "block_type": "dark_oak_slab"
    },
    {
      "x": 10,
      "y": 12,
      "z": 7,
      "block_type": "dark_oak_slab"
    },
    {
      "x": 0,
      "y": 12,
      "z": 8,
      "block_type": "dark_oak_slab"
    },
    {
      "x": 10,
      "y": 12,
      "z": 8,
      "block_type": "dark_oak_slab"
    },
    {
      "x": 0,
      "y": 12,
      "z": 9,
      "block_type": "dark_oak_slab"
    },
    {
      "x": 10,
      "y": 12,
      "z": 9,
      "block_type": "dark_oak_slab"
    },
    {
      "x": 2,
      "y": 12,
      "z": 2,
      "block_type": "oak_fence"
    },
    {
      "x": 2,
      "y": 12,
      "z": 3,
      "block_type": "dark_oak_planks"
    },
    {
      "x": 2,
      "y": 12,
      "z": 4,
      "block_type": "dark_oak_planks"
    },
    {
      "x": 2,
      "y": 12,
      "z": 5,
      "block_type": "dark_oak_planks"
    },
    {
      "x": 2,
      "y": 12,
      "z": 6,
      "block_type": "dark_oak_planks"
    },
    {
      "x": 2,
      "y": 12,
      "z": 7,
      "block_type": "dark_oak_planks"
    },
    {
      "x": 2,
      "y": 12,
      "z": 8,
      "block_type": "oak_fence"
    },
    {
      "x": 8,
      "y": 12,
      "z": 2,
      "block_type": "oak_fence"
    },
    {
      "x": 8,
      "y": 12,
      "z": 3,
      "block_type": "dark_oak_planks"
    },
    {
      "x": 8,
      "y": 12,
      "z": 4,
      "block_type": "dark_oak_planks"
    },
    {
      "x": 8,
      "y": 12,
      "z": 5,
      "block_type": "dark_oak_planks"
    },
    {
      "x": 8,
      "y": 12,
      "z": 6,
      "block_type": "dark_oak_planks"
    },
    {
      "x": 8,
      "y": 12,
      "z": 7,
      "block_type": "dark_oak_planks"
    },
    {
      "x": 8,
      "y": 12,
      "z": 8,
      "block_type": "oak_fence"
    },
    {
      "x": 3,
      "y": 12,
      "z": 2,
      "block_type": "dark_oak_planks"
    },
    {
      "x": 4,
      "y": 12,
      "z": 2,
      "block_type": "dark_oak_planks"
    },
    {
      "x": 5,
      "y": 12,
      "z": 2,
      "block_type": "dark_oak_planks"
    },
    {
      "x": 6,
      "y": 12,
      "z": 2,
      "block_type": "dark_oak_planks"
    },
    {
      "x": 7,
      "y": 12,
      "z": 2,
      "block_type": "dark_oak_planks"
    },
    {
      "x": 3,
      "y": 12,
      "z": 8,
      "block_type": "dark_oak_planks"
    },
    {
      "x": 4,
      "y": 12,
      "z": 8,
      "block_type": "dark_oak_planks"
    },
    {
      "x": 5,
      "y": 12,
      "z": 8,
      "block_type": "dark_oak_planks"
    },
    {
      "x": 6,
      "y": 12,
      "z": 8,
      "block_type": "dark_oak_planks"
    },
    {
      "x": 7,
      "y": 12,
      "z": 8,
      "block_type": "dark_oak_planks"
    },
    {
      "x": 2,
      "y": 13,
      "z": 2,
      "block_type": "oak_fence"
    },
    {
      "x": 2,
      "y": 13,
      "z": 3,
      "block_type": "dark_oak_planks"
    },
    {
      "x": 2,
      "y": 13,
      "z": 4,
      "block_type": "dark_oak_planks"
    },
    {
      "x": 2,
      "y": 13,
      "z": 5,
      "block_type": "dark_oak_planks"
    },
    {
      "x": 2,
      "y": 13,
      "z": 6,
      "block_type": "dark_oak_planks"
    },
    {
      "x": 2,
      "y": 13,
      "z": 7,
      "block_type": "dark_oak_planks"
    },
    {
      "x": 2,
      "y": 13,
      "z": 8,
      "block_type": "oak_fence"
    },
    {
      "x": 8,
      "y": 13,
      "z": 2,
      "block_type": "oak_fence"
    },
    {
      "x": 8,
      "y": 13,
      "z": 3,
      "block_type": "dark_oak_planks"
    },
    {
      "x": 8,
      "y": 13,
      "z": 4,
      "block_type": "dark_oak_planks"
    },
    {
      "x": 8,
      "y": 13,
      "z": 5,
      "block_type": "dark_oak_planks"
    },
    {
      "x": 8,
      "y": 13,
      "z": 6,
      "block_type": "dark_oak_planks"
    },
    {
      "x": 8,
      "y": 13,
      "z": 7,
      "block_type": "dark_oak_planks"
    },
    {
      "x": 8,
      "y": 13,
      "z": 8,
      "block_type": "oak_fence"
    },
    {
      "x": 3,
      "y": 13,
      "z": 2,
      "block_type": "dark_oak_planks"
    },
    {
      "x": 4,
      "y": 13,
      "z": 2,
      "block_type": "dark_oak_planks"
    },
    {
      "x": 5,
      "y": 13,
      "z": 2,
      "block_type": "dark_oak_planks"
    },
    {
      "x": 6,
      "y": 13,
      "z": 2,
      "block_type": "dark_oak_planks"
    },
    {
      "x": 7,
      "y": 13,
      "z": 2,
      "block_type": "dark_oak_planks"
    },
    {
      "x": 3,
      "y": 13,
      "z": 8,
      "block_type": "dark_oak_planks"
    },
    {
      "x": 4,
      "y": 13,
      "z": 8,
      "block_type": "dark_oak_planks"
    },
    {
      "x": 5,
      "y": 13,
      "z": 8,
      "block_type": "dark_oak_planks"
    },
    {
      "x": 6,
      "y": 13,
      "z": 8,
      "block_type": "dark_oak_planks"
    },
    {
      "x": 7,
      "y": 13,
      "z": 8,
      "block_type": "dark_oak_planks"
    },
    {
      "x": 2,
      "y": 14,
      "z": 2,
      "block_type": "oak_fence"
    },
    {
      "x": 2,
      "y": 14,
      "z": 3,
      "block_type": "dark_oak_planks"
    },
    {
      "x": 2,
      "y": 14,
      "z": 4,
      "block_type": "dark_oak_planks"
    },
    {
      "x": 2,
      "y": 14,
      "z": 5,
      "block_type": "dark_oak_planks"
    },
    {
      "x": 2,
      "y": 14,
      "z": 6,
      "block_type": "dark_oak_planks"
    },
    {
      "x": 2,
      "y": 14,
      "z": 7,
      "block_type": "dark_oak_planks"
    },
    {
      "x": 2,
      "y": 14,
      "z": 8,
      "block_type": "oak_fence"
    },
    {
      "x": 8,
      "y": 14,
      "z": 2,
      "block_type": "oak_fence"
    },
    {
      "x": 8,
      "y": 14,
      "z": 3,
      "block_type": "dark_oak_planks"
    },
    {
      "x": 8,
      "y": 14,
      "z": 4,
      "block_type": "dark_oak_planks"
    },
    {
      "x": 8,
      "y": 14,
      "z": 5,
      "block_type": "dark_oak_planks"
    },
    {
      "x": 8,
      "y": 14,
      "z": 6,
      "block_type": "dark_oak_planks"
    },
    {
      "x": 8,
      "y": 14,
      "z": 7,
      "block_type": "dark_oak_planks"
    },
    {
      "x": 8,
      "y": 14,
      "z": 8,
      "block_type": "oak_fence"
    },
    {
      "x": 3,
      "y": 14,
      "z": 2,
      "block_type": "dark_oak_planks"
    },
    {
      "x": 4,
      "y": 14,
      "z": 2,
      "block_type": "dark_oak_planks"
    },
    {
      "x": 5,
      "y": 14,
      "z": 2,
      "block_type": "dark_oak_planks"
    },
    {
      "x": 6,
      "y": 14,
      "z": 2,
      "block_type": "dark_oak_planks"
    },
    {
      "x": 7,
      "y": 14,
      "z": 2,
      "block_type": "dark_oak_planks"
    },
    {
      "x": 3,
      "y": 14,
      "z": 8,
      "block_type": "dark_oak_planks"
    },
    {
      "x": 4,
      "y": 14,
      "z": 8,
      "block_type": "dark_oak_planks"
    },
    {
      "x": 5,
      "y": 14,
      "z": 8,
      "block_type": "dark_oak_planks"
    },
    {
      "x": 6,
      "y": 14,
      "z": 8,
      "block_type": "dark_oak_planks"
    },
    {
      "x": 7,
      "y": 14,
      "z": 8,
      "block_type": "dark_oak_planks"
    },
    {
      "x": 2,
      "y": 15,
      "z": 2,
      "block_type": "oak_fence"
    },
    {
      "x": 2,
      "y": 15,
      "z": 3,
      "block_type": "dark_oak_planks"
    },
    {
      "x": 2,
      "y": 15,
      "z": 4,
      "block_type": "dark_oak_planks"
    },
    {
      "x": 2,
      "y": 15,
      "z": 5,
      "block_type": "dark_oak_planks"
    },
    {
      "x": 2,
      "y": 15,
      "z": 6,
      "block_type": "dark_oak_planks"
    },
    {
      "x": 2,
      "y": 15,
      "z": 7,
      "block_type": "dark_oak_planks"
    },
    {
      "x": 2,
      "y": 15,
      "z": 8,
      "block_type": "oak_fence"
    },
    {
      "x": 8,
      "y": 15,
      "z": 2,
      "block_type": "oak_fence"
    },
    {
      "x": 8,
      "y": 15,
      "z": 3,
      "block_type": "dark_oak_planks"
    },
    {
      "x": 8,
      "y": 15,
      "z": 4,
      "block_type": "dark_oak_planks"
    },
    {
      "x": 8,
      "y": 15,
      "z": 5,
      "block_type": "dark_oak_planks"
    },
    {
      "x": 8,
      "y": 15,
      "z": 6,
      "block_type": "dark_oak_planks"
    },
    {
      "x": 8,
      "y": 15,
      "z": 7,
      "block_type": "dark_oak_planks"
    },
    {
      "x": 8,
      "y": 15,
      "z": 8,
      "block_type": "oak_fence"
    },
    {
      "x": 3,
      "y": 15,
      "z": 2,
      "block_type": "dark_oak_planks"
    },
    {
      "x": 4,
      "y": 15,
      "z": 2,
      "block_type": "dark_oak_planks"
    },
    {
      "x": 5,
      "y": 15,
      "z": 2,
      "block_type": "dark_oak_planks"
    },
    {
      "x": 6,
      "y": 15,
      "z": 2,
      "block_type": "dark_oak_planks"
    },
    {
      "x": 7,
      "y": 15,
      "z": 2,
      "block_type": "dark_oak_planks"
    },
    {
      "x": 3,
      "y": 15,
      "z": 8,
      "block_type": "dark_oak_planks"
    },
    {
      "x": 4,
      "y": 15,
      "z": 8,
      "block_type": "dark_oak_planks"
    },
    {
      "x": 5,
      "y": 15,
      "z": 8,
      "block_type": "dark_oak_planks"
    },
    {
      "x": 6,
      "y": 15,
      "z": 8,
      "block_type": "dark_oak_planks"
    },
    {
      "x": 7,
      "y": 15,
      "z": 8,
      "block_type": "dark_oak_planks"
    },
    {
      "x": 2,
      "y": 16,
      "z": 2,
      "block_type": "oak_fence"
    },
    {
      "x": 2,
      "y": 16,
      "z": 3,
      "block_type": "dark_oak_planks"
    },
    {
      "x": 2,
      "y": 16,
      "z": 4,
      "block_type": "dark_oak_planks"
    },
    {
      "x": 2,
      "y": 16,
      "z": 5,
      "block_type": "dark_oak_planks"
    },
    {
      "x": 2,
      "y": 16,
      "z": 6,
      "block_type": "dark_oak_planks"
    },
    {
      "x": 2,
      "y": 16,
      "z": 7,
      "block_type": "dark_oak_planks"
    },
    {
      "x": 2,
      "y": 16,
      "z": 8,
      "block_type": "oak_fence"
    },
    {
      "x": 8,
      "y": 16,
      "z": 2,
      "block_type": "oak_fence"
    },
    {
      "x": 8,
      "y": 16,
      "z": 3,
      "block_type": "dark_oak_planks"
    },
    {
      "x": 8,
      "y": 16,
      "z": 4,
      "block_type": "dark_oak_planks"
    },
    {
      "x": 8,
      "y": 16,
      "z": 5,
      "block_type": "dark_oak_planks"
    },
    {
      "x": 8,
      "y": 16,
      "z": 6,
      "block_type": "dark_oak_planks"
    },
    {
      "x": 8,
      "y": 16,
      "z": 7,
      "block_type": "dark_oak_planks"
    },
    {
      "x": 8,
      "y": 16,
      "z": 8,
      "block_type": "oak_fence"
    },
    {
      "x": 3,
      "y": 16,
      "z": 2,
      "block_type": "dark_oak_planks"
    },
    {
      "x": 4,
      "y": 16,
      "z": 2,
      "block_type": "dark_oak_planks"
    },
    {
      "x": 5,
      "y": 16,
      "z": 2,
      "block_type": "dark_oak_planks"
    },
    {
      "x": 6,
      "y": 16,
      "z": 2,
      "block_type": "dark_oak_planks"
    },
    {
      "x": 7,
      "y": 16,
      "z": 2,
      "block_type": "dark_oak_planks"
    },
    {
      "x": 3,
      "y": 16,
      "z": 8,
      "block_type": "dark_oak_planks"
    },
    {
      "x": 4,
      "y": 16,
      "z": 8,
      "block_type": "dark_oak_planks"
    },
    {
      "x": 5,
      "y": 16,
      "z": 8,
      "block_type": "dark_oak_planks"
    },
    {
      "x": 6,
      "y": 16,
      "z": 8,
      "block_type": "dark_oak_planks"
    },
    {
      "x": 7,
      "y": 16,
      "z": 8,
      "block_type": "dark_oak_planks"
    },
    {
      "x": 1,
      "y": 17,
      "z": 1,
      "block_type": "dark_oak_slab"
    },
    {
      "x": 1,
      "y": 17,
      "z": 9,
      "block_type": "dark_oak_slab"
    },
    {
      "x": 2,
      "y": 17,
      "z": 1,
      "block_type": "dark_oak_slab"
    },
    {
      "x": 2,
      "y": 17,
      "z": 9,
      "block_type": "dark_oak_slab"
    },
    {
      "x": 3,
      "y": 17,
      "z": 1,
      "block_type": "dark_oak_slab"
    },
    {
      "x": 3,
      "y": 17,
      "z": 9,
      "block_type": "dark_oak_slab"
    },
    {
      "x": 4,
      "y": 17,
      "z": 1,
      "block_type": "dark_oak_slab"
    },
    {
      "x": 4,
      "y": 17,
      "z": 9,
      "block_type": "dark_oak_slab"
    },
    {
      "x": 5,
      "y": 17,
      "z": 1,
      "block_type": "dark_oak_slab"
    },
    {
      "x": 5,
      "y": 17,
      "z": 9,
      "block_type": "dark_oak_slab"
    },
    {
      "x": 6,
      "y": 17,
      "z": 1,
      "block_type": "dark_oak_slab"
    },
    {
      "x": 6,
      "y": 17,
      "z": 9,
      "block_type": "dark_oak_slab"
    },
    {
      "x": 7,
      "y": 17,
      "z": 1,
      "block_type": "dark_oak_slab"
    },
    {
      "x": 7,
      "y": 17,
      "z": 9,
      "block_type": "dark_oak_slab"
    },
    {
      "x": 8,
      "y": 17,
      "z": 1,
      "block_type": "dark_oak_slab"
    },
    {
      "x": 8,
      "y": 17,
      "z": 9,
      "block_type": "dark_oak_slab"
    },
    {
      "x": 9,
      "y": 17,
      "z": 1,
      "block_type": "dark_oak_slab"
    },
    {
      "x": 9,
      "y": 17,
      "z": 9,
      "block_type": "dark_oak_slab"
    },
    {
      "x": 1,
      "y": 17,
      "z": 2,
      "block_type": "dark_oak_slab"
    },
    {
      "x": 9,
      "y": 17,
      "z": 2,
      "block_type": "dark_oak_slab"
    },
    {
      "x": 1,
      "y": 17,
      "z": 3,
      "block_type": "dark_oak_slab"
    },
    {
      "x": 9,
      "y": 17,
      "z": 3,
      "block_type": "dark_oak_slab"
    },
    {
      "x": 1,
      "y": 17,
      "z": 4,
      "block_type": "dark_oak_slab"
    },
    {
      "x": 9,
      "y": 17,
      "z": 4,
      "block_type": "dark_oak_slab"
    },
    {
      "x": 1,
      "y": 17,
      "z": 5,
      "block_type": "dark_oak_slab"
    },
    {
      "x": 9,
      "y": 17,
      "z": 5,
      "block_type": "dark_oak_slab"
    },
    {
      "x": 1,
      "y": 17,
      "z": 6,
      "block_type": "dark_oak_slab"
    },
    {
      "x": 9,
      "y": 17,
      "z": 6,
      "block_type": "dark_oak_slab"
    },
    {
      "x": 1,
      "y": 17,
      "z": 7,
      "block_type": "dark_oak_slab"
    },
    {
      "x": 9,
      "y": 17,
      "z": 7,
      "block_type": "dark_oak_slab"
    },
    {
      "x": 1,
      "y": 17,
      "z": 8,
      "block_type": "dark_oak_slab"
    },
    {
      "x": 9,
      "y": 17,
      "z": 8,
      "block_type": "dark_oak_slab"
    },
    {
      "x": 3,
      "y": 17,
      "z": 3,
      "block_type": "oak_fence"
    },
    {
      "x": 3,
      "y": 17,
      "z": 4,
      "block_type": "dark_oak_planks"
    },
    {
      "x": 3,
      "y": 17,
      "z": 5,
      "block_type": "dark_oak_planks"
    },
    {
      "x": 3,
      "y": 17,
      "z": 6,
      "block_type": "dark_oak_planks"
    },
    {
      "x": 3,
      "y": 17,
      "z": 7,
      "block_type": "oak_fence"
    },
    {
      "x": 7,
      "y": 17,
      "z": 3,
      "block_type": "oak_fence"
    },
    {
      "x": 7,
      "y": 17,
      "z": 4,
      "block_type": "dark_oak_planks"
    },
    {
      "x": 7,
      "y": 17,
      "z": 5,
      "block_type": "dark_oak_planks"
    },
    {
      "x": 7,
      "y": 17,
      "z": 6,
      "block_type": "dark_oak_planks"
    },
    {
      "x": 7,
      "y": 17,
      "z": 7,
      "block_type": "oak_fence"
    },
    {
      "x": 4,
      "y": 17,
      "z": 3,
      "block_type": "dark_oak_planks"
    },
    {
      "x": 5,
      "y": 17,
      "z": 3,
      "block_type": "dark_oak_planks"
    },
    {
      "x": 6,
      "y": 17,
      "z": 3,
      "block_type": "dark_oak_planks"
    },
    {
      "x": 4,
      "y": 17,
      "z": 7,
      "block_type": "dark_oak_planks"
    },
    {
      "x": 5,
      "y": 17,
      "z": 7,
      "block_type": "dark_oak_planks"
    },
    {
      "x": 6,
      "y": 17,
      "z": 7,
      "block_type": "dark_oak_planks"
    },
    {
      "x": 3,
      "y": 18,
      "z": 3,
      "block_type": "oak_fence"
    },
    {
      "x": 3,
      "y": 18,
      "z": 4,
      "block_type": "dark_oak_planks"
    },
    {
      "x": 3,
      "y": 18,
      "z": 5,
      "block_type": "dark_oak_planks"
    },
    {
      "x": 3,
      "y": 18,
      "z": 6,
      "block_type": "dark_oak_planks"
    },
    {
      "x": 3,
      "y": 18,
      "z": 7,
      "block_type": "oak_fence"
    },
    {
      "x": 7,
      "y": 18,
      "z": 3,
      "block_type": "oak_fence"
    },
    {
      "x": 7,
      "y": 18,
      "z": 4,
      "block_type": "dark_oak_planks"
    },
    {
      "x": 7,
      "y": 18,
      "z": 5,
      "block_type": "dark_oak_planks"
    },
    {
      "x": 7,
      "y": 18,
      "z": 6,
      "block_type": "dark_oak_planks"
    },
    {
      "x": 7,
      "y": 18,
      "z": 7,
      "block_type": "oak_fence"
    },
    {
      "x": 4,
      "y": 18,
      "z": 3,
      "block_type": "dark_oak_planks"
    },
    {
      "x": 5,
      "y": 18,
      "z": 3,
      "block_type": "dark_oak_planks"
    },
    {
      "x": 6,
      "y": 18,
      "z": 3,
      "block_type": "dark_oak_planks"
    },
    {
      "x": 4,
      "y": 18,
      "z": 7,
      "block_type": "dark_oak_planks"
    },
    {
      "x": 5,
      "y": 18,
      "z": 7,
      "block_type": "dark_oak_planks"
    },
    {
      "x": 6,
      "y": 18,
      "z": 7,
      "block_type": "dark_oak_planks"
    },
    {
      "x": 3,
      "y": 19,
      "z": 3,
      "block_type": "oak_fence"
    },
    {
      "x": 3,
      "y": 19,
      "z": 4,
      "block_type": "dark_oak_planks"
    },
    {
      "x": 3,
      "y": 19,
      "z": 5,
      "block_type": "dark_oak_planks"
    },
    {
      "x": 3,
      "y": 19,
      "z": 6,
      "block_type": "dark_oak_planks"
    },
    {
      "x": 3,
      "y": 19,
      "z": 7,
      "block_type": "oak_fence"
    },
    {
      "x": 7,
      "y": 19,
      "z": 3,
      "block_type": "oak_fence"
    },
    {
      "x": 7,
      "y": 19,
      "z": 4,
      "block_type": "dark_oak_planks"
    },
    {
      "x": 7,
      "y": 19,
      "z": 5,
      "block_type": "dark_oak_planks"
    },
    {
      "x": 7,
      "y": 19,
      "z": 6,
      "block_type": "dark_oak_planks"
    },
    {
      "x": 7,
      "y": 19,
      "z": 7,
      "block_type": "oak_fence"
    },
    {
      "x": 4,
      "y": 19,
      "z": 3,
      "block_type": "dark_oak_planks"
    },
    {
      "x": 5,
      "y": 19,
      "z": 3,
      "block_type": "dark_oak_planks"
    },
    {
      "x": 6,
      "y": 19,
      "z": 3,
      "block_type": "dark_oak_planks"
    },
    {
      "x": 4,
      "y": 19,
      "z": 7,
      "block_type": "dark_oak_planks"
    },
    {
      "x": 5,
      "y": 19,
      "z": 7,
      "block_type": "dark_oak_planks"
    },
    {
      "x": 6,
      "y": 19,
      "z": 7,
      "block_type": "dark_oak_planks"
    },
    {
      "x": 3,
      "y": 20,
      "z": 3,
      "block_type": "oak_fence"
    },
    {
      "x": 3,
      "y": 20,
      "z": 4,
      "block_type": "dark_oak_planks"
    },
    {
      "x": 3,
      "y": 20,
      "z": 5,
      "block_type": "dark_oak_planks"
    },
    {
      "x": 3,
      "y": 20,
      "z": 6,
      "block_type": "dark_oak_planks"
    },
    {
      "x": 3,
      "y": 20,
      "z": 7,
      "block_type": "oak_fence"
    },
    {
      "x": 7,
      "y": 20,
      "z": 3,
      "block_type": "oak_fence"
    },
    {
      "x": 7,
      "y": 20,
      "z": 4,
      "block_type": "dark_oak_planks"
    },
    {
      "x": 7,
      "y": 20,
      "z": 5,
      "block_type": "dark_oak_planks"
    },
    {
      "x": 7,
      "y": 20,
      "z": 6,
      "block_type": "dark_oak_planks"
    },
    {
      "x": 7,
      "y": 20,
      "z": 7,
      "block_type": "oak_fence"
    },
    {
      "x": 4,
      "y": 20,
      "z": 3,
      "block_type": "dark_oak_planks"
    },
    {
      "x": 5,
      "y": 20,
      "z": 3,
      "block_type": "dark_oak_planks"
    },
    {
      "x": 6,
      "y": 20,
      "z": 3,
      "block_type": "dark_oak_planks"
    },
    {
      "x": 4,
      "y": 20,
      "z": 7,
      "block_type": "dark_oak_planks"
    },
    {
      "x": 5,
      "y": 20,
      "z": 7,
      "block_type": "dark_oak_planks"
    },
    {
      "x": 6,
      "y": 20,
      "z": 7,
      "block_type": "dark_oak_planks"
    },
    {
      "x": 2,
      "y": 21,
      "z": 2,
      "block_type": "dark_oak_slab"
    },
    {
      "x": 2,
      "y": 21,
      "z": 8,
      "block_type": "dark_oak_slab"
    },
    {
      "x": 3,
      "y": 21,
      "z": 2,
      "block_type": "dark_oak_slab"
    },
    {
      "x": 3,
      "y": 21,
      "z": 8,
      "block_type": "dark_oak_slab"
    },
    {
      "x": 4,
      "y": 21,
      "z": 2,
      "block_type": "dark_oak_slab"
    },
    {
      "x": 4,
      "y": 21,
      "z": 8,
      "block_type": "dark_oak_slab"
    },
    {
      "x": 5,
      "y": 21,
      "z": 2,
      "block_type": "dark_oak_slab"
    },
    {
      "x": 5,
      "y": 21,
      "z": 8,
      "block_type": "dark_oak_slab"
    },
    {
      "x": 6,
      "y": 21,
      "z": 2,
      "block_type": "dark_oak_slab"
    },
    {
      "x": 6,
      "y": 21,
      "z": 8,
      "block_type": "dark_oak_slab"
    },
    {
      "x": 7,
      "y": 21,
      "z": 2,
      "block_type": "dark_oak_slab"
    },
    {
      "x": 7,
      "y": 21,
      "z": 8,
      "block_type": "dark_oak_slab"
    },
    {
      "x": 8,
      "y": 21,
      "z": 2,
      "block_type": "dark_oak_slab"
    },
    {
      "x": 8,
      "y": 21,
      "z": 8,
      "block_type": "dark_oak_slab"
    },
    {
      "x": 2,
      "y": 21,
      "z": 3,
      "block_type": "dark_oak_slab"
    },
    {
      "x": 8,
      "y": 21,
      "z": 3,
      "block_type": "dark_oak_slab"
    },
    {
      "x": 2,
      "y": 21,
      "z": 4,
      "block_type": "dark_oak_slab"
    },
    {
      "x": 8,
      "y": 21,
      "z": 4,
      "block_type": "dark_oak_slab"
    },
    {
      "x": 2,
      "y": 21,
      "z": 5,
      "block_type": "dark_oak_slab"
    },
    {
      "x": 8,
      "y": 21,
      "z": 5,
      "block_type": "dark_oak_slab"
    },
    {
      "x": 2,
      "y": 21,
      "z": 6,
      "block_type": "dark_oak_slab"
    },
    {
      "x": 8,
      "y": 21,
      "z": 6,
      "block_type": "dark_oak_slab"
    },
    {
      "x": 2,
      "y": 21,
      "z": 7,
      "block_type": "dark_oak_slab"
    },
    {
      "x": 8,
      "y": 21,
      "z": 7,
      "block_type": "dark_oak_slab"
    }
  ]
}